Workbook

Sheet __FDSCACHE__
B1: This sheet contains FactSet XML data for use with this workbook's =FDS codes. Modifying the worksheet's contents may damage the workbook's =FDS functionality.

Sheet CONFIG
A1: No. | B1: 한국어명 | C1: 영문명 | D1: FactSet Code | E1: MSCI 분류 | F1: Free Float Ratio (추정) | G1: MSCI 구성종목수 (추정) | H1: 대표지수 | I1: FactSet Ticker | J1: Bloomberg 참조
A2: 1 | B2: 미국 | C2: USA | D2: CC_US | E2: DM | F2: 0.93 | G2: 583 | H2: S&P 500 | I2: SP50 | J2: SPX
A3: 2 | B3: 일본 | C3: Japan | D3: CC_JP | E3: DM | F3: 0.72 | G3: 203 | H3: TOPIX | I3: 100000018-TK | J3: TPX
A4: 3 | B4: 영국 | C4: UK | D4: CC_GB | E4: DM | F4: 0.88 | G4: 78 | H4: FTSE 100 | I4: 990100-GB | J4: UKX
A5: 4 | B5: 프랑스 | C5: France | D5: CC_FR | E5: DM | F5: 0.82 | G5: 62 | H5: CAC 40 | I5: 990100-FR | J5: CAC
A6: 5 | B6: 캐나다 | C6: Canada | D6: CC_CA | E6: DM | F6: 0.87 | G6: 85 | H6: S&P/TSX Composite | I6: SP60-CA | J6: SPTSX
A7: 6 | B7: 스위스 | C7: Switzerland | D7: CC_CH | E7: DM | F7: 0.85 | G7: 42 | H7: SMI | I7: 990100-CH | J7: SMI
A8: 7 | B8: 독일 | C8: Germany | D8: CC_DE | E8: DM | F8: 0.8 | G8: 55 | H8: DAX | I8: DAX-FF | J8: DAX
A9: 8 | B9: 호주 | C9: Australia | D9: CC_AU | E9: DM | F9: 0.85 | G9: 56 | H9: S&P/ASX 200 | I9: 990100-AU | J9: AS51
A10: 9 | B10: 네덜란드 | C10: Netherlands | D10: CC_NL | E10: DM | F10: 0.88 | G10: 23 | H10: AEX | I10: 990100-NL | J10: AEX
A11: 10 | B11: 스웨덴 | C11: Sweden | D11: CC_SE | E11: DM | F11: 0.82 | G11: 40 | H11: OMX Stockholm 30 | I11: 990100-SE | J11: OMX
A12: 11 | B12: 덴마크 | C12: Denmark | D12: CC_DK | E12: DM | F12: 0.78 | G12: 16 | H12: OMX Copenhagen 20 | I12: 990100-DK | J12: KFX
A13: 12 | B13: 스페인 | C13: Spain | D13: CC_ES | E13: DM | F13: 0.75 | G13: 20 | H13: IBEX 35 | I13: 990100-ES | J13: IBEX
... A48: 47 | B48: 페루 | C48: Peru | D48: CC_PE | E48: EM | F48: 0.5 | G48: 3 | H48: S&P/BVL Peru | I48: 990100-PE | J48: IGBVL
A50: 참고사항
A51: 1. Free Float Ratio는 MSCI 방법론 기준 추정치입니다. 실제 MSCI 데이터 구독시 정확한 값으로 교체하세요.
A52: 2. 구성종목수는 2024년말 기준 대략적인 추정치입니다.
A53: 3. FactSet에서 FDS_ECON_STMK_FFMC_USD_M 가 지원된다면 FREE_FLOAT_MC 시트 대신 직접 사용 권장
A54: 4. 유동시가총액 = 국가 전체 시총 × MSCI Coverage(~85%) × Free Float Ratio

Sheet GDP
A1: GDP | B1: 미국 | C1: 일본 | D1: 영국 | E1: 프랑스 | F1: 캐나다 | G1: 스위스 | H1: 독일 | I1: 호주 | J1: 네덜란드 | K1: 스웨덴 | L1: 덴마크 | M1: 스페인 | N1: 이탈리아 | O1: 홍콩 | P1: 싱가포르 | Q1: 벨기에 | R1: 핀란드 | S1: 이스라엘 | T1: 노르웨이 | U1: 아일랜드 | V1: 뉴질랜드 | W1: 오스트리아 | X1: 포르투갈 | Y1: 중국 | Z1: 인도 | AA1: 대만 | AB1: 한국 | AC1: 브라질 | AD1: 사우디아라비아 | AE1: 남아프리카공화국 | AF1: 멕시코 | AG1: 인도네시아 | AH1: 말레이시아 | AI1: 아랍에미리트 | AJ1: 태국 | AK1: 쿠웨이트 | AL1: 카타르 | AM1: 폴란드 | AN1: 칠레 | AO1: 튀르키예 | AP1: 그리스 | AQ1: 필리핀 | AR1: 헝가리 | AS1: 이집트 | AT1: 체코 | AU1: 콜롬비아 | AV1: 페루
A2: USD Millions | B2: USA | C2: Japan | D2: UK | E2: France | F2: Canada | G2: Switzerland | H2: Germany | I2: Australia | J2: Netherlands | K2: Sweden | L2: Denmark | M2: Spain | N2: Italy | O2: Hong Kong | P2: Singapore | Q2: Belgium | R2: Finland | S2: Israel | T2: Norway | U2: Ireland | V2: New Zealand | W2: Austria | X2: Portugal | Y2: China | Z2: India | AA2: Taiwan | AB2: Korea | AC2: Brazil | AD2: Saudi Arabia | AE2: South Africa | AF2: Mexico | AG2: Indonesia | AH2: Malaysia | AI2: UAE | AJ2: Thailand | AK2: Kuwait | AL2: Qatar | AM2: Poland | AN2: Chile | AO2: Turkey | AP2: Greece | AQ2: Philippines | AR2: Hungary | AS2: Egypt | AT2: Czech Republic | AU2: Colombia | AV2: Peru
A3: =_xll.FDS("CC_US","FG_COMPANY_NAME()") -> #NAME? | B3: CC_US | C3: CC_JP | D3: CC_GB | E3: CC_FR | F3: CC_CA | G3: CC_CH | H3: CC_DE | I3: CC_AU | J3: CC_NL | K3: CC_SE | L3: CC_DK | M3: CC_ES | N3: CC_IT | O3: CC_HK | P3: CC_SG | Q3: CC_BE | R3: CC_FI | S3: CC_IL | T3: CC_NO | U3: CC_IE | V3: CC_NZ | W3: CC_AT | X3: CC_PT | Y3: CC_CN | Z3: CC_IN | AA3: CC_TW | AB3: CC_KR | AC3: CC_BR | AD3: CC_SA | AE3: CC_ZA | AF3: CC_MX | AG3: CC_ID | AH3: CC_MY | AI3: CC_AE | AJ3: CC_TH | AK3: CC_KW | AL3: CC_QA | AM3: CC_PL | AN3: CC_CL | AO3: CC_TR | AP3: CC_GR | AQ3: CC_PH | AR3: CC_HU | AS3: CC_EG | AT3: CC_CZ | AU3: CC_CO | AV3: CC_PE
A4: 46022 | B4: {=_xll.FDS(B3,"FDS_ECON_GDP_USD_Q(3/9/2026,1/1/2000)")} -> #NAME? | C4: {=_xll.FDS(C3,"FDS_ECON_GDP_USD_Q(3/9/2026,1/1/2000)")} -> #NAME? | D4: {=_xll.FDS(D3,"FDS_ECON_GDP_USD_Q(3/9/2026,1/1/2000)")} -> #NAME? | E4: {=_xll.FDS(E3,"FDS_ECON_GDP_USD_Q(3/9/2026,1/1/2000)")} -> #NAME? | F4: {=_xll.FDS(F3,"FDS_ECON_GDP_USD_Q(3/9/2026,1/1/2000)")} -> #NAME? | G4: {=_xll.FDS(G3,"FDS_ECON_GDP_USD_Q(3/9/2026,1/1/2000)")} -> #NAME? | H4: {=_xll.FDS(H3,"FDS_ECON_GDP_USD_Q(3/9/2026,1/1/2000)")} -> #NAME? | I4: {=_xll.FDS(I3,"FDS_ECON_GDP_USD_Q(3/9/2026,1/1/2000)")} -> #NAME? | ... AV4: {=_xll.FDS(AV3,"FDS_ECON_GDP_USD_Q(3/9/2026,1/1/2000)")} -> #NAME?
A5: {=_xll.FDS("CC_US","JULIAN(P_DATE(3/9/2026,1/1/2000,CQ).dates)")} -> #NAME? | B5: #NAME? | C5: #NAME? | D5: #NAME? | E5: #NAME? | F5: #NAME? | G5: #NAME? | H5: #NAME? | I5: #NAME? | J5: #NAME? | K5: #NAME? | L5: #NAME? | M5: #NAME? | N5: #NAME? | O5: #NAME? | P5: #NAME? | Q5: #NAME? | R5: #NAME? | S5: #NAME? | T5: #NAME? | U5: #NAME? | V5: #NAME? | W5: #NAME? | X5: #NAME? | Y5: #NAME? | Z5: #NAME? | AA5: #NAME? | AB5: #NAME? | AC5: #NAME? | AD5: #NAME? | AE5: #NAME? | AF5: #NAME? | AG5: #NAME? | AH5: #NAME? | AI5: #NAME? | AJ5: #NAME? | AK5: #NAME? | AL5: #NAME? | AM5: #NAME? | AN5: #NAME? | AO5: #NAME? | AP5: #NAME? | AQ5: #NAME? | AR5: #NAME? | AS5: #NAME? | AT5: #NAME? | AU5: #NAME? | AV5: #NAME?
A6: #NAME? | B6: #NAME? | C6: #NAME? | D6: #NAME? | E6: #NAME? | F6: #NAME? | G6: #NAME? | H6: #NAME? | I6: #NAME? | J6: #NAME? | K6: #NAME? | L6: #NAME? | M6: #NAME? | N6: #NAME? | O6: #NAME? | P6: #NAME? | Q6: #NAME? | R6: #NAME? | S6: #NAME? | T6: #NAME? | U6: #NAME? | V6: #NAME? | W6: #NAME? | X6: #NAME? | Y6: #NAME? | Z6: #NAME? | AA6: #NAME? | AB6: #NAME? | AC6: #NAME? | AD6: #NAME? | AE6: #NAME? | AF6: #NAME? | AG6: #NAME? | AH6: #NAME? | AI6: #NAME? | AJ6: #NAME? | AK6: #NAME? | AL6: #NAME? | AM6: #NAME? | AN6: #NAME? | AO6: #NAME? | AP6: #NAME? | AQ6: #NAME? | AR6: #NAME? | AS6: #NAME? | AT6: #NAME? | AU6: #NAME? | AV6: #NAME?
A7: #NAME? | B7: #NAME? | C7: #NAME? | D7: #NAME? | E7: #NAME? | F7: #NAME? | G7: #NAME? | H7: #NAME? | I7: #NAME? | J7: #NAME? | K7: #NAME? | L7: #NAME? | M7: #NAME? | N7: #NAME? | O7: #NAME? | P7: #NAME? | Q7: #NAME? | R7: #NAME? | S7: #NAME? | T7: #NAME? | U7: #NAME? | V7: #NAME? | W7: #NAME? | X7: #NAME? | Y7: #NAME? | Z7: #NAME? | AA7: #NAME? | AB7: #NAME? | AC7: #NAME? | AD7: #NAME? | AE7: #NAME? | AF7: #NAME? | AG7: #NAME? | AH7: #NAME? | AI7: #NAME? | AJ7: #NAME? | AK7: #NAME? | AL7: #NAME? | AM7: #NAME? | AN7: #NAME? | AO7: #NAME? | AP7: #NAME? | AQ7: #NAME? | AR7: #NAME? | AS7: #NAME? | AT7: #NAME? | AU7: #NAME? | AV7: #NAME?
A8: #NAME? | B8: #NAME? | C8: #NAME? | D8: #NAME? | E8: #NAME? | F8: #NAME? | G8: #NAME? | H8: #NAME? | I8: #NAME? | J8: #NAME? | K8: #NAME? | L8: #NAME? | M8: #NAME? | N8: #NAME? | O8: #NAME? | P8: #NAME? | Q8: #NAME? | R8: #NAME? | S8: #NAME? | T8: #NAME? | U8: #NAME? | V8: #NAME? | W8: #NAME? | X8: #NAME? | Y8: #NAME? | Z8: #NAME? | AA8: #NAME? | AB8: #NAME? | AC8: #NAME? | AD8: #NAME? | AE8: #NAME? | AF8: #NAME? | AG8: #NAME? | AH8: #NAME? | AI8: #NAME? | AJ8: #NAME? | AK8: #NAME? | AL8: #NAME? | AM8: #NAME? | AN8: #NAME? | AO8: #NAME? | AP8: #NAME? | AQ8: #NAME? | AR8: #NAME? | AS8: #NAME? | AT8: #NAME? | AU8: #NAME? | AV8: #NAME?
A9: #NAME? | B9: #NAME? | C9: #NAME? | D9: #NAME? | E9: #NAME? | F9: #NAME? | G9: #NAME? | H9: #NAME? | I9: #NAME? | J9: #NAME? | K9: #NAME? | L9: #NAME? | M9: #NAME? | N9: #NAME? | O9: #NAME? | P9: #NAME? | Q9: #NAME? | R9: #NAME? | S9: #NAME? | T9: #NAME? | U9: #NAME? | V9: #NAME? | W9: #NAME? | X9: #NAME? | Y9: #NAME? | Z9: #NAME? | AA9: #NAME? | AB9: #NAME? | AC9: #NAME? | AD9: #NAME? | AE9: #NAME? | AF9: #NAME? | AG9: #NAME? | AH9: #NAME? | AI9: #NAME? | AJ9: #NAME? | AK9: #NAME? | AL9: #NAME? | AM9: #NAME? | AN9: #NAME? | AO9: #NAME? | AP9: #NAME? | AQ9: #NAME? | AR9: #NAME? | AS9: #NAME? | AT9: #NAME? | AU9: #NAME? | AV9: #NAME?
A10: #NAME? | B10: #NAME? | C10: #NAME? | D10: #NAME? | E10: #NAME? | F10: #NAME? | G10: #NAME? | H10: #NAME? | I10: #NAME? | J10: #NAME? | K10: #NAME? | L10: #NAME? | M10: #NAME? | N10: #NAME? | O10: #NAME? | P10: #NAME? | Q10: #NAME? | R10: #NAME? | S10: #NAME? | T10: #NAME? | U10: #NAME? | V10: #NAME? | W10: #NAME? | X10: #NAME? | Y10: #NAME? | Z10: #NAME? | AA10: #NAME? | AB10: #NAME? | AC10: #NAME? | AD10: #NAME? | AE10: #NAME? | AF10: #NAME? | AG10: #NAME? | AH10: #NAME? | AI10: #NAME? | AJ10: #NAME? | AK10: #NAME? | AL10: #NAME? | AM10: #NAME? | AN10: #NAME? | AO10: #NAME? | AP10: #NAME? | AQ10: #NAME? | AR10: #NAME? | AS10: #NAME? | AT10: #NAME? | AU10: #NAME? | AV10: #NAME?
A11: #NAME? | B11: #NAME? | C11: #NAME? | D11: #NAME? | E11: #NAME? | F11: #NAME? | G11: #NAME? | H11: #NAME? | I11: #NAME? | J11: #NAME? | K11: #NAME? | L11: #NAME? | M11: #NAME? | N11: #NAME? | O11: #NAME? | P11: #NAME? | Q11: #NAME? | R11: #NAME? | S11: #NAME? | T11: #NAME? | U11: #NAME? | V11: #NAME? | W11: #NAME? | X11: #NAME? | Y11: #NAME? | Z11: #NAME? | AA11: #NAME? | AB11: #NAME? | AC11: #NAME? | AD11: #NAME? | AE11: #NAME? | AF11: #NAME? | AG11: #NAME? | AH11: #NAME? | AI11: #NAME? | AJ11: #NAME? | AK11: #NAME? | AL11: #NAME? | AM11: #NAME? | AN11: #NAME? | AO11: #NAME? | AP11: #NAME? | AQ11: #NAME? | AR11: #NAME? | AS11: #NAME? | AT11: #NAME? | AU11: #NAME? | AV11: #NAME?
A12: #NAME? | B12: #NAME? | C12: #NAME? | D12: #NAME? | E12: #NAME? | F12: #NAME? | G12: #NAME? | H12: #NAME? | I12: #NAME? | J12: #NAME? | K12: #NAME? | L12: #NAME? | M12: #NAME? | N12: #NAME? | O12: #NAME? | P12: #NAME? | Q12: #NAME? | R12: #NAME? | S12: #NAME? | T12: #NAME? | U12: #NAME? | V12: #NAME? | W12: #NAME? | X12: #NAME? | Y12: #NAME? | Z12: #NAME? | AA12: #NAME? | AB12: #NAME? | AC12: #NAME? | AD12: #NAME? | AE12: #NAME? | AF12: #NAME? | AG12: #NAME? | AH12: #NAME? | AI12: #NAME? | AJ12: #NAME? | AK12: #NAME? | AL12: #NAME? | AM12: #NAME? | AN12: #NAME? | AO12: #NAME? | AP12: #NAME? | AQ12: #NAME? | AR12: #NAME? | AS12: #NAME? | AT12: #NAME? | AU12: #NAME? | AV12: #NAME?
A13: #NAME? | B13: #NAME? | C13: #NAME? | D13: #NAME? | E13: #NAME? | F13: #NAME? | G13: #NAME? | H13: #NAME? | I13: #NAME? | J13: #NAME? | K13: #NAME? | L13: #NAME? | M13: #NAME? | N13: #NAME? | O13: #NAME? | P13: #NAME? | Q13: #NAME? | R13: #NAME? | S13: #NAME? | T13: #NAME? | U13: #NAME? | V13: #NAME? | W13: #NAME? | X13: #NAME? | Y13: #NAME? | Z13: #NAME? | AA13: #NAME? | AB13: #NAME? | AC13: #NAME? | AD13: #NAME? | AE13: #NAME? | AF13: #NAME? | AG13: #NAME? | AH13: #NAME? | AI13: #NAME? | AJ13: #NAME? | AK13: #NAME? | AL13: #NAME? | AM13: #NAME? | AN13: #NAME? | AO13: #NAME? | AP13: #NAME? | AQ13: #NAME? | AR13: #NAME? | AS13: #NAME? | AT13: #NAME? | AU13: #NAME? | AV13: #NAME?
A14: #NAME? | B14: #NAME? | C14: #NAME? | D14: #NAME? | E14: #NAME? | F14: #NAME? | G14: #NAME? | H14: #NAME? | I14: #NAME? | J14: #NAME? | K14: #NAME? | L14: #NAME? | M14: #NAME? | N14: #NAME? | O14: #NAME? | P14: #NAME? | Q14: #NAME? | R14: #NAME? | S14: #NAME? | T14: #NAME? | U14: #NAME? | V14: #NAME? | W14: #NAME? | X14: #NAME? | Y14: #NAME? | Z14: #NAME? | AA14: #NAME? | AB14: #NAME? | AC14: #NAME? | AD14: #NAME? | AE14: #NAME? | AF14: #NAME? | AG14: #NAME? | AH14: #NAME? | AI14: #NAME? | AJ14: #NAME? | AK14: #NAME? | AL14: #NAME? | AM14: #NAME? | AN14: #NAME? | AO14: #NAME? | AP14: #NAME? | AQ14: #NAME? | AR14: #NAME? | AS14: #NAME? | AT14: #NAME? | AU14: #NAME? | AV14: #NAME?
A15: #NAME? | B15: #NAME? | C15: #NAME? | D15: #NAME? | E15: #NAME? | F15: #NAME? | G15: #NAME? | H15: #NAME? | I15: #NAME? | J15: #NAME? | K15: #NAME? | L15: #NAME? | M15: #NAME? | N15: #NAME? | O15: #NAME? | P15: #NAME? | Q15: #NAME? | R15: #NAME? | S15: #NAME? | T15: #NAME? | U15: #NAME? | V15: #NAME? | W15: #NAME? | X15: #NAME? | Y15: #NAME? | Z15: #NAME? | AA15: #NAME? | AB15: #NAME? | AC15: #NAME? | AD15: #NAME? | AE15: #NAME? | AF15: #NAME? | AG15: #NAME? | AH15: #NAME? | AI15: #NAME? | AJ15: #NAME? | AK15: #NAME? | AL15: #NAME? | AM15: #NAME? | AN15: #NAME? | AO15: #NAME? | AP15: #NAME? | AQ15: #NAME? | AR15: #NAME? | AS15: #NAME? | AT15: #NAME? | AU15: #NAME? | AV15: #NAME?
A16: #NAME? | B16: #NAME? | C16: #NAME? | D16: #NAME? | E16: #NAME? | F16: #NAME? | G16: #NAME? | H16: #NAME? | I16: #NAME? | J16: #NAME? | K16: #NAME? | L16: #NAME? | M16: #NAME? | N16: #NAME? | O16: #NAME? | P16: #NAME? | Q16: #NAME? | R16: #NAME? | S16: #NAME? | T16: #NAME? | U16: #NAME? | V16: #NAME? | W16: #NAME? | X16: #NAME? | Y16: #NAME? | Z16: #NAME? | AA16: #NAME? | AB16: #NAME? | AC16: #NAME? | AD16: #NAME? | AE16: #NAME? | AF16: #NAME? | AG16: #NAME? | AH16: #NAME? | AI16: #NAME? | AJ16: #NAME? | AK16: #NAME? | AL16: #NAME? | AM16: #NAME? | AN16: #NAME? | AO16: #NAME? | AP16: #NAME? | AQ16: #NAME? | AR16: #NAME? | AS16: #NAME? | AT16: #NAME? | AU16: #NAME? | AV16: #NAME?
A17: #NAME? | B17: #NAME? | C17: #NAME? | D17: #NAME? | E17: #NAME? | F17: #NAME? | G17: #NAME? | H17: #NAME? | I17: #NAME? | J17: #NAME? | K17: #NAME? | L17: #NAME? | M17: #NAME? | N17: #NAME? | O17: #NAME? | P17: #NAME? | Q17: #NAME? | R17: #NAME? | S17: #NAME? | T17: #NAME? | U17: #NAME? | V17: #NAME? | W17: #NAME? | X17: #NAME? | Y17: #NAME? | Z17: #NAME? | AA17: #NAME? | AB17: #NAME? | AC17: #NAME? | AD17: #NAME? | AE17: #NAME? | AF17: #NAME? | AG17: #NAME? | AH17: #NAME? | AI17: #NAME? | AJ17: #NAME? | AK17: #NAME? | AL17: #NAME? | AM17: #NAME? | AN17: #NAME? | AO17: #NAME? | AP17: #NAME? | AQ17: #NAME? | AR17: #NAME? | AS17: #NAME? | AT17: #NAME? | AU17: #NAME? | AV17: #NAME?
... A108: #NAME? | B108: #NAME? | C108: #NAME? | D108: #NAME? | E108: #NAME? | F108: #NAME? | G108: #NAME? | H108: #NAME? | I108: #NAME? | J108: #NAME? | K108: #NAME? | L108: #NAME? | M108: #NAME? | N108: #NAME? | O108: #NAME? | P108: #NAME? | Q108: #NAME? | R108: #NAME? | S108: #NAME? | T108: #NAME? | U108: #NAME? | V108: #NAME? | W108: #NAME? | X108: #NAME? | Y108: #NAME? | Z108: #NAME? | AA108: #NAME? | AB108: #NAME? | AC108: #NAME? | AD108: #NAME? | AE108: #NAME? | AF108: #NAME? | AG108: #NAME? | AH108: #NAME? | AI108: #NAME? | AJ108: #NAME? | AK108: #NAME? | AL108: #NAME? | AM108: #NAME? | AN108: #NAME? | AO108: #NAME? | AP108: #NAME? | AQ108: #NAME? | AR108: #NAME? | AS108: #NAME? | AT108: #NAME? | AU108: #NAME? | AV108: #NAME?

Sheet Sheet4
A1: GDP | B1: 미국 | C1: 일본 | D1: 영국 | E1: 프랑스 | F1: 캐나다 | G1: 스위스 | H1: 독일 | I1: 호주 | J1: 네덜란드 | K1: 스웨덴 | L1: 덴마크 | M1: 스페인 | N1: 이탈리아 | O1: 홍콩 | P1: 싱가포르 | Q1: 벨기에 | R1: 핀란드 | S1: 이스라엘 | T1: 노르웨이 | U1: 아일랜드 | V1: 뉴질랜드 | W1: 오스트리아 | X1: 포르투갈 | Y1: 중국 | Z1: 인도 | AA1: 대만 | AB1: 한국 | AC1: 브라질 | AD1: 사우디아라비아 | AE1: 남아프리카공화국 | AF1: 멕시코 | AG1: 인도네시아 | AH1: 말레이시아 | AI1: 아랍에미리트 | AJ1: 태국 | AK1: 쿠웨이트 | AL1: 카타르 | AM1: 폴란드 | AN1: 칠레 | AO1: 튀르키예 | AP1: 그리스 | AQ1: 필리핀 | AR1: 헝가리 | AS1: 이집트 | AT1: 체코 | AU1: 콜롬비아 | AV1: 페루
A2: USD Millions | B2: USA | C2: Japan | D2: UK | E2: France | F2: Canada | G2: Switzerland | H2: Germany | I2: Australia | J2: Netherlands | K2: Sweden | L2: Denmark | M2: Spain | N2: Italy | O2: Hong Kong | P2: Singapore | Q2: Belgium | R2: Finland | S2: Israel | T2: Norway | U2: Ireland | V2: New Zealand | W2: Austria | X2: Portugal | Y2: China | Z2: India | AA2: Taiwan | AB2: Korea | AC2: Brazil | AD2: Saudi Arabia | AE2: South Africa | AF2: Mexico | AG2: Indonesia | AH2: Malaysia | AI2: UAE | AJ2: Thailand | AK2: Kuwait | AL2: Qatar | AM2: Poland | AN2: Chile | AO2: Turkey | AP2: Greece | AQ2: Philippines | AR2: Hungary | AS2: Egypt | AT2: Czech Republic | AU2: Colombia | AV2: Peru
A3: United States | B3: CC_US | C3: CC_JP | D3: CC_GB | E3: CC_FR | F3: CC_CA | G3: CC_CH | H3: CC_DE | I3: CC_AU | J3: CC_NL | K3: CC_SE | L3: CC_DK | M3: CC_ES | N3: CC_IT | O3: CC_HK | P3: CC_SG | Q3: CC_BE | R3: CC_FI | S3: CC_IL | T3: CC_NO | U3: CC_IE | V3: CC_NZ | W3: CC_AT | X3: CC_PT | Y3: CC_CN | Z3: CC_IN | AA3: CC_TW | AB3: CC_KR | AC3: CC_BR | AD3: CC_SA | AE3: CC_ZA | AF3: CC_MX | AG3: CC_ID | AH3: CC_MY | AI3: CC_AE | AJ3: CC_TH | AK3: CC_KW | AL3: CC_QA | AM3: CC_PL | AN3: CC_CL | AO3: CC_TR | AP3: CC_GR | AQ3: CC_PH | AR3: CC_HU | AS3: CC_EG | AT3: CC_CZ | AU3: CC_CO | AV3: CC_PE
A4: 46022 | B4: 31442.482 | C4: 4359.741 | D4: 4089.4558 | E4: 3501.0361 | F4: 2351.545 | G4: 1080.9624 | H4: 5281.0107 | I4: 1920.7183 | J4: 1399.164 | K4: 743.11926 | L4: 483.81903 | M4: 2023.4791 | N4: 2810.1848 | O4: 453.64917 | P4: 630.1347 | Q4: #N/A | R4: 329.98547 | S4: 682.6327 | T4: 535.4186 | U4: 731.76306 | V4: 259.50345 | W4: 602.8467 | X4: 365.30655 | Y4: 21883.088 | Z4: 4081.845 | AA4: 998.70386 | AB4: 1908.2041 | AC4: 2429.9307 | AD4: 1290.7953 | AE4: 459.75726 | AF4: #N/A | AG4: 1476.7533 | AH4: 512.9805 | AI4: #N/A | AJ4: 596.82214 | AK4: #N/A | AL4: #N/A | AM4: #N/A | AN4: 375.76212 | AO4: 1684.7858 | AP4: 297.22238 | AQ4: 539.17395 | AR4: 294.9197 | AS4: #N/A | AT4: 419.48093 | AU4: 495.0757 | AV4: 389.5818
A5: 46022 | B5: 31442.482 | C5: 4359.741 | D5: 4089.4558 | E5: 3501.0361 | F5: 2351.545 | G5: 1080.9624 | H5: 5281.0107 | I5: 1920.7183 | J5: 1399.164 | K5: 743.11926 | L5: 483.81903 | M5: 2023.4791 | N5: 2810.1848 | O5: 453.64917 | P5: 630.1347 | Q5: #N/A | R5: 329.98547 | S5: 682.6327 | T5: 535.4186 | U5: 731.76306 | V5: 259.50345 | W5: 602.8467 | X5: 365.30655 | Y5: 21883.088 | Z5: 4081.845 | AA5: 998.70386 | AB5: 1908.2041 | AC5: 2429.9307 | AD5: 1290.7953 | AE5: 459.75726 | AF5: #N/A | AG5: 1476.7533 | AH5: 512.9805 | AI5: #N/A | AJ5: 596.82214 | AK5: #N/A | AL5: #N/A | AM5: #N/A | AN5: 375.76212 | AO5: 1684.7858 | AP5: 297.22238 | AQ5: 539.17395 | AR5: 294.9197 | AS5: #N/A | AT5: 419.48093 | AU5: 495.0757 | AV5: 389.5818
A6: 45930 | B6: 31098.027 | C6: 4512.742 | D6: 4119.1216 | E6: 3495.991 | F6: 2366.3938 | G6: 1079.9146 | H6: 5241.423 | I6: 1879.2029 | J6: 1387.581 | K6: 673.2325 | L6: 482.93262 | M6: 1973.805 | N6: 2636.0352 | O6: 438.67245 | P6: 621.295 | Q6: 752.4947 | R6: 328.1886 | S6: 642.60516 | T6: 543.96454 | U6: 741.38135 | V6: 264.66406 | W6: 603.9788 | X6: 363.02045 | Y6: 19788.908 | Z6: 3666.11 | AA6: 959.1781 | AB6: 1917.0343 | AC6: 2375.0889 | AD6: 1274.1874 | AE6: 437.54736 | AF6: 1893.8525 | AG6: 1481.3643 | AH6: 489.48608 | AI6: 577.4785 | AJ6: 582.7558 | AK6: 158.26462 | AL6: 216.34763 | AM6: 1065.227 | AN6: 355.7942 | AO6: 1619.8162 | AP6: 316.6572 | AQ6: 459.09833 | AR6: 266.22626 | AS6: 464.82156 | AT6: 410.6555 | AU6: 470.4702 | AV6: 349.6865
A7: 45838 | B7: 30485.7 | C7: 4608.899 | D7: 4043.2937 | E7: 3364.9875 | F7: 2319.7695 | G7: 1054.286 | H7: 5055.1313 | I7: 1807.0771 | J7: 1328.4016 | K7: 688.2791 | L7: 458.63684 | M7: 1890.3102 | N7: 2523.7585 | O7: 404.49237 | P7: 591.7965 | Q7: 725.21686 | R7: 316.4073 | S7: 566.4045 | T7: 536.9076 | U7: 735.3772 | V7: 261.34067 | W7: 579.376 | X7: 344.5481 | Y7: 18875.79 | Z7: 3754.4458 | AA7: 900.7978 | AB7: 1884.0167 | AC7: 2257.8472 | AD7: 1258.7874 | AE7: 412.7394 | AF7: 1802.8038 | AG7: 1442.6259 | AH7: 453.32022 | AI7: 580.84875 | AJ7: 571.9509 | AK7: 151.67088 | AL7: 211.9156 | AM7: 988.1642 | AN7: 357.3799 | AO7: 1562.4407 | AP7: 279.6163 | AQ7: 495.2262 | AR7: 245.83495 | AS7: 348.37955 | AT7: 386.38675 | AU7: 434.9545 | AV7: 325.18204
A8: 45747 | B8: 30042.113 | C8: 4280.2656 | D8: 3770.503 | E8: 3113.6472 | F8: 2246.7888 | G8: 969.34955 | H8: 4665.1377 | I8: 1757.1267 | J8: 1219.4886 | K8: 584.58435 | L8: 426.7342 | M8: 1736.113 | N8: 2249.866 | O8: 412.79147 | P8: 573.02423 | Q8: 668.87683 | R8: 293.769 | S8: 560.4293 | T8: 513.50366 | U8: 681.3145 | V8: 249.69441 | W8: 533.5989 | X8: 314.4536 | Y8: 17509.12 | Z8: 4005.148 | AA8: 828.7545 | AB8: 1783.4402 | AC8: 2070.6245 | AD8: 1282.264 | AE8: 402.0618 | AF8: 1705.3824 | AG8: 1386.1367 | AH8: 436.10458 | AI8: 547.30365 | AJ8: 557.1767 | AK8: 163.1674 | AL8: 220.44601 | AM8: 895.90643 | AN8: 341.16165 | AO8: 1491.7755 | AP8: 232.19594 | AQ8: 454.319 | AR8: 187.01425 | AS8: 360.9427 | AT8: 350.1392 | AU8: 432.85907 | AV8: 297.14874
A9: 45657 | B9: 29825.182 | C9: 4239.81 | D9: 3784.1672 | E9: 3140.2432 | F9: 2271.83 | G9: 983.24927 | H9: 4671.9595 | I9: 1800.7053 | J9: 1222.0419 | K9: 630.9273 | L9: 437.59875 | M9: 1740.5073 | N9: 2499.8823 | O9: 431.69376 | P9: 587.5796 | Q9: 669.1744 | R9: 296.54767 | S9: 571.9762 | T9: 495.03085 | U9: 652.2318 | V9: 255.61617 | W9: 532.39355 | X9: 315.99695 | Y9: 20784.79 | Z9: 3953.3982 | AA9: 815.62177 | AB9: 1861.878 | AC9: 2100.0972 | AD9: 1263.98 | AE9: 416.80377 | AF9: 1700.9628 | AG9: 1437.0416 | AH9: 456.49313 | AI9: 561.5801 | AJ9: 555.5909 | AK9: 159.6655 | AL9: 222.65852 | AM9: 1020.4271 | AN9: 333.95627 | AO9: 1450.574 | AP9: 260.84177 | AQ9: 521.51874 | AR9: 240.84402 | AS9: 369.30988 | AT9: 346.86652 | AU9: 411.5866 | AV9: 319.7422
A10: 45565 | B10: 29511.664 | C10: 4286.9307 | D10: 3792.271 | E10: 3232.9636 | F10: 2295.8362 | G10: 992.1268 | H10: 4763.4966 | I10: 1825.8219 | J10: 1239.4398 | K10: 593.4914 | L10: 433.94373 | M10: 1757.9589 | N10: 2407.5361 | O10: 420.564 | P10: 600.01587 | Q10: 685.2146 | R10: 304.6071 | S10: 550.2432 | T10: 502.98807 | U10: 626.5018 | V10: 261.0957 | W10: 544.0894 | X10: 320.49234 | Y10: 19056.424 | Z10: 3522.6978 | AA10: 803.0601 | AB10: 1872.021 | AC10: 2175.6323 | AD10: 1242.8812 | AE10: 409.86084 | AF10: 1791.2885 | AG10: 1429.5438 | AH10: 440.07294 | AI10: 557.5448 | AJ10: 540.761 | AK10: 156.92946 | AL10: 218.85841 | AM10: 937.114 | AN10: 337.1426 | AO10: 1384.8534 | AP10: 284.08032 | AQ10: 437.3991 | AR10: 236.55005 | AS10: 380.7095 | AT10: 353.52386 | AU10: 420.8222 | AV10: 302.8586
A11: 45471 | B11: 29147.045 | C11: 4057.6013 | D11: 3619.1963 | E11: 3122.363 | F11: 2257.4563 | G11: 942.1218 | H11: 4642.4316 | I11: 1786.9475 | J11: 1199.5505 | K11: 605.99286 | L11: 415.4229 | M11: 1701.0704 | N11: 2337.4978 | O11: 388.48615 | P11: 553.19415 | Q11: 664.92566 | R11: 296.15677 | S11: 521.3301 | T11: 508.15485 | U11: 591.0022 | V11: 257.65085 | W11: 529.814 | X11: 309.12497 | Y11: 18148.707 | Z11: 3552.3987 | AA11: 784.4234 | AB11: 1861.9634 | AC11: 2253.37 | AD11: 1265.4358 | AE11: 394.7313 | AF11: 1917.0107 | AG11: 1372.2476 | AH11: 401.1734 | AI11: 561.53827 | AJ11: 509.09204 | AK11: 163.99846 | AL11: 212.47116 | AM11: 872.2151 | AN11: 326.3752 | AO11: 1307.8347 | AP11: 252.4074 | AQ11: 449.4997 | AR11: 226.98843 | AS11: 296.47516 | AT11: 345.12292 | AU11: 432.49487 | AV11: 293.52625
A12: 45379 | B12: 28708.16 | C12: 4169.784 | D12: 3581.149 | E12: 3146.1675 | F12: 2251.3433 | G12: 963.3732 | H12: 4664.8955 | I12: 1777.4384 | J12: 1195.8839 | K12: 586.60864 | L12: 410.86935 | M12: 1699.1586 | N12: 2281.5015 | O12: 393.0436 | P12: 547.68524 | Q12: 664.74005 | R12: 296.97397 | S12: 524.3523 | T12: 498.66837 | U12: 565.2348 | V12: 259.26782 | W12: 530.55927 | X12: 308.30627 | Y12: 16945.504 | Z12: 3815.462 | AA12: 802.738 | AB12: 1906.5785 | AC12: 2233.0647 | AD12: 1241.1348 | AE12: 383.35782 | AF12: 1926.6307 | AG12: 1351.2284 | AH12: 394.65942 | AI12: 528.3847 | AJ12: 514.747 | AK12: 162.48763 | AL12: 214.0883 | AM12: 841.0628 | AN12: 321.44135 | AO12: 1273.5875 | AP12: 227.27155 | AQ12: 437.27795 | AR12: 185.54858 | AS12: 401.30612 | AT12: 342.11417 | AU12: 418.4901 | AV12: 265.43008
A13: 45289 | B13: 28424.723 | C13: 4214.699 | D13: 3425.3398 | E13: 3100.566 | F13: 2214.216 | G13: 943.9872 | H13: 4607.416 | I13: 1735.1733 | J13: 1169.9203 | K13: 609.61115 | L13: 399.74667 | M13: 1655.3578 | N13: 2450.8308 | O13: 406.13516 | P13: 516.692 | Q13: 653.3125 | R13: 291.97473 | S13: 499.8896 | T13: 495.89023 | U13: 559.4047 | V13: 250.66692 | W13: 517.68134 | X13: 296.54044 | Y13: 19763.338 | Z13: 3641.5044 | AA13: 773.91644 | AB13: 1867.2025 | AC13: 2312.124 | AD13: 1229.7394 | AE13: 383.03305 | AF13: 1858.1417 | AG13: 1357.69 | AH13: 404.59647 | AI13: 537.17664 | AJ13: 506.70148 | AK13: 170.07117 | AL13: 216.25162 | AM13: 920.43835 | AN13: 322.41858 | AO13: 1167.018 | AP13: 250.20224 | AQ13: 502.86328 | AR13: 238.76437 | AS13: 445.42493 | AT13: 341.32858 | AU13: 394.484 | AV13: 289.4406
A14: 45198 | B14: 28074.846 | C14: 4270.7544 | D14: 3507.6296 | E14: 3095.8079 | F14: 2234.9307 | G14: 943.8621 | H14: 4613.839 | I14: 1725.2345 | J14: 1170.4491 | K14: 553.4323 | L14: 401.82715 | M14: 1627.6049 | N14: 2329.7244 | O14: 391.4993 | P14: 510.92505 | Q14: 658.10443 | R14: 296.90967 | S14: 516.53406 | T14: 491.73602 | U14: 574.1271 | V14: 252.80087 | W14: 519.8539 | X14: 296.91797 | Y14: 18128.598 | Z14: 3279.1003 | AA14: 760.32715 | AB14: 1844.0819 | AC14: 2268.64 | AD14: 1219.2424 | AE14: 379.5424 | AF14: 1889.3992 | AG14: 1391.5588 | AH14: 399.85162 | AI14: 521.9527 | AJ14: 515.8568 | AK14: 168.00247 | AL14: 220.38464 | AM14: 824.12744 | AN14: 331.80038 | AO14: 1109.7312 | AP14: 266.48187 | AQ14: 411.50507 | AR14: 222.54208 | AS14: 434.5183 | AT14: 345.88687 | AU14: 392.19214 | AV14: 280.67575
A15: 45107 | B15: 27530.055 | C15: 4494.2715 | D15: 3452.7388 | E15: 3077.1697 | F15: 2185.2988 | G15: 924.7988 | H15: 4573.2046 | I15: 1738.4595 | J15: 1155.0935 | K15: 590.6682 | L15: 406.87134 | M15: 1609.9073 | N15: 2312.3528 | O15: 359.00385 | P15: 506.11096 | Q15: 653.31366 | R15: 299.63287 | S15: 510.9786 | T15: 488.08646 | U15: 577.956 | V15: 255.11334 | W15: 519.3394 | X15: 292.0392 | Y15: 18027.088 | Z15: 3262.889 | AA15: 753.0078 | AB15: 1814.0778 | AC15: 2202.9048 | AD15: 1201.7004 | AE15: 374.11676 | AF15: 1783.5681 | AG15: 1405.7805 | AH15: 390.01883 | AI15: 525.16 | AJ15: 518.3315 | AK15: 158.00418 | AL15: 211.91211 | AM15: 785.8805 | AN15: 347.4896 | AO15: 1144.3789 | AP15: 241.81229 | AQ15: 423.176 | AR15: 218.85732 | AS15: 337.29755 | AT15: 354.15033 | AU15: 357.1736 | AV15: 271.91818
A16: 45016 | B16: 27216.445 | C16: 4575.518 | D16: 3301.3013 | E16: 2966.0715 | F16: 2152.7744 | G16: 902.6108 | H16: 4458.6255 | I16: 1783.1566 | J16: 1121.6932 | K16: 561.62396 | L16: 409.5787 | M16: 1584.0345 | N16: 2173.4854 | O16: 366.58142 | P16: 508.37405 | Q16: 640.2857 | R16: 292.13464 | S16: 515.1 | T16: 532.5612 | U16: 559.83344 | V16: 254.25414 | W16: 512.22015 | X16: 283.67218 | Y16: 17088.55 | Z16: 3453.811 | AA16: 739.9096 | AB16: 1846.421 | AC16: 1987.7478 | AD16: 1221.4054 | AE16: 388.4821 | AF16: 1662.347 | AG16: 1332.605 | AH16: 405.2899 | AI16: 506.02383 | AJ16: 528.08716 | AK16: 165.23892 | AL16: 217.55556 | AM16: 726.4896 | AN16: 343.15552 | AO16: 1127.4135 | AP16: 213.45277 | AQ16: 409.68954 | AR16: 173.9751 | AS16: 343.52487 | AT16: 340.43402 | AU16: 330.66788 | AV16: 246.53966
A17: 44925 | B17: 26770.514 | C17: 4196.4063 | D17: 3134.3052 | E17: 2776.6956 | F17: 2129.4219 | G17: 861.44183 | H17: 4160.699 | I17: 1681.7623 | J17: 1049.386 | K17: 583.1911 | L17: 390.67993 | M17: 1463.8525 | N17: 2197.9863 | O17: 374.30606 | P17: 494.03864 | Q17: 593.66864 | R17: 276.10977 | S17: 536.87854 | T17: 553.3272 | U17: 550.6596 | V17: 240.84247 | W17: 469.30276 | X17: 259.5284 | Y17: 19244.05 | Z17: 3331.5972 | AA17: 729.03595 | AB17: 1713.8184 | AC17: 2010.6022 | AD17: 1230.8873 | AE17: 382.62476 | AF17: 1547.1647 | AG17: 1314.3779 | AH17: 408.76123 | AI17: 507.01965 | AJ17: 483.9829 | AK17: 175.64474 | AL17: 238.74341 | AM17: 761.94946 | AN17: 300.4463 | AO17: 1013.5051 | AP17: 219.83691 | AQ17: 450.28403 | AR17: 186.78902 | AS17: 435.89096 | AT17: 304.88504 | AU17: 316.20038 | AV17: 266.3189
... A60: 40998 | B60: 16068.805 | C60: 6451.128 | D60: 2681.9316 | E60: 2730.257 | F60: 1812.9747 | G60: 706.2339 | H60: 3646.3435 | I60: 1584.869 | J60: 859.67804 | K60: 525.7708 | L60: 329.81927 | M60: 1378.1055 | N60: 2045.7704 | O60: 249.30507 | P60: 290.2454 | Q60: 507.05344 | R60: 263.3103 | S60: 259.8221 | T60: 532.8709 | U60: 230.4588 | V60: 175.61081 | W60: 411.24734 | X60: 224.67122 | Y60: 7438.3003 | Z60: 1925.9927 | AA60: 485.08102 | AB60: 1322.4325 | AC60: 2556.2498 | AD60: 761.99475 | AE60: 448.71793 | AF60: 1252.0521 | AG60: 909.3928 | AH60: 307.19498 | AI60: 392.22504 | AJ60: 381.50125 | AK60: 183.10527 | AL60: 186.84892 | AM60: 460.11972 | AN60: 260.98126 | AO60: 843.5809 | AP60: 233.30891 | AQ60: 236.1134 | AR60: 114.41952 | AS60: 266.95706 | AT60: 215.4195 | AU60: 366.34033 | AV60: 176.75238
A61: 40907 | B61: 15842.259 | C61: 6532.799 | D61: 2648.9736 | E61: 2799.1697 | F61: 1772.1719 | G61: 708.0433 | H61: 3733.5627 | I61: 1516.9734 | J61: 884.48413 | K61: 573.37573 | L61: 336.87228 | M61: 1421.7771 | N61: 2356.853 | O61: 266.80466 | P61: 276.4165 | Q61: 515.0489 | R61: 268.59796 | S61: 265.17798 | T61: 510.85413 | U61: 231.17157 | V61: 166.75035 | W61: 415.64935 | X61: 232.9504 | Y61: 8681.187 | Z61: 1766.165 | AA61: 467.28552 | AB61: 1297.0817 | AC61: 2582.292 | AD61: 710.4399 | AE61: 424.15894 | AF61: 1173.3613 | AG61: 898.346 | AH61: 302.32477 | AI61: #N/A | AJ61: 344.80814 | AK61: 167.40175 | AL61: 175.45847 | AM61: 524.8379 | AN61: 245.28737 | AO61: 814.766 | AP61: 274.05948 | AQ61: 259.64877 | AR61: 141.02734 | AS61: 282.18146 | AT61: 219.9039 | AU61: 336.68756 | AV61: 182.65709
A62: 40816 | B62: 15647.68 | C62: 6499.361 | D62: 2691.0864 | E62: 2907.8364 | F62: 1820.881 | G62: 780.4058 | H62: 3892.384 | I62: 1566.6163 | J62: 927.76526 | K62: 558.395 | L62: 347.2204 | M62: 1505.221 | N62: 2327.0095 | O62: 254.29959 | P62: 289.42172 | Q62: 536.2781 | R62: 279.89896 | S62: 274.27933 | T62: 526.37634 | U62: 244.75288 | V62: 177.43274 | W62: 437.43115 | X62: 248.60745 | Y62: 7890.062 | Z62: 1770.6105 | AA62: 497.4194 | AB62: 1338.871 | AC62: 2717.8328 | AD62: 688.4408 | AE62: 470.65616 | AF62: 1248.5632 | AG62: 955.67645 | AH62: 306.34604 | AI62: #N/A | AJ62: 386.87234 | AK62: 155.3491 | AL62: 175.19373 | AM62: 509.6969 | AN62: 256.28766 | AO62: 829.3776 | AP62: 293.2549 | AQ62: 227.25945 | AR62: 149.34976 | AS62: 287.2574 | AT62: 237.51175 | AU62: 348.42706 | AV62: 174.8896
A63: 40724 | B63: 15557.539 | C63: 6061.006 | D63: 2699.5225 | E63: 2956.3838 | F63: 1817.6249 | G63: 745.13086 | H63: 3929.5776 | I63: 1559.0624 | J63: 943.4429 | K63: 607.64264 | L63: 357.569 | M63: 1548.4817 | N63: 2387.087 | O63: 234.82872 | P63: 279.58414 | Q63: 543.60754 | R63: 283.6517 | S63: 274.6693 | T63: 525.3199 | U63: 250.7577 | V63: 168.125 | W63: 441.35992 | X63: 254.771 | Y63: 7317.133 | Z63: 1827.4286 | AA63: 487.33783 | AB63: 1323.7566 | AC63: 2724.395 | AD63: 686.258 | AE63: 484.47064 | AF63: 1278.1935 | AG63: 897.9271 | AH63: 296.9077 | AI63: #N/A | AJ63: 376.15543 | AK63: 153.06311 | AL63: 168.16489 | AM63: 536.38806 | AN63: 256.5042 | AO63: 881.88983 | AP63: 298.40286 | AQ63: 235.4089 | AR63: 150.85541 | AS63: 234.90347 | AT63: 241.76381 | AU63: 339.97284 | AV63: 169.25674
A64: 40633 | B64: 15351.448 | C64: 6097.992 | D64: 2669.268 | E64: 2808.175 | F64: 1763.2274 | G64: 685.17303 | H64: 3718.2253 | I64: 1439.5059 | J64: 894.2515 | K64: 544.1897 | L64: 339.3682 | M64: 1474.0784 | N64: 2152.481 | O64: 238.05916 | P64: 272.87692 | Q64: 513.2504 | R64: 268.04712 | S64: 257.19302 | T64: 489.32092 | U64: 236.40585 | V64: 156.18759 | W64: 420.48343 | X64: 245.25957 | Y64: 6347.8174 | Z64: 1950.8646 | AA64: 489.3346 | AB64: 1270.8126 | AC64: 2440.278 | AD64: 637.31195 | AE64: 459.6551 | AF64: 1217.8231 | AG64: 824.6659 | AH64: 286.53427 | AI64: #N/A | AJ64: 375.76746 | AK64: 139.5486 | AL64: 152.04037 | AM64: 483.7201 | AN64: 250.28693 | AO64: 845.4319 | AP64: 267.3765 | AQ64: 214.82559 | AR64: 126.22894 | AS64: 215.20853 | AT64: 227.67339 | AU64: 315.63095 | AV64: 156.20465
A65: 40543 | B65: 15309.474 | C65: 6183.0503 | D65: 2582.4675 | E65: 2732.0537 | F65: 1680.2234 | G65: 660.36725 | H65: 3618.47 | I65: 1391.5703 | J65: 880.9256 | K65: 567.3831 | L65: 333.73065 | M65: 1469.0981 | N65: 2360.9978 | O65: 249.37897 | P65: 260.20078 | Q65: 501.40894 | R65: 263.0954 | S65: 248.31438 | T65: 463.32822 | U65: 227.55077 | V65: 155.51828 | W65: 406.03012 | X65: 245.33289 | Y65: 7169.774 | Z65: 1824.1432 | AA65: 465.13953 | AB65: 1250.4567 | AC65: 2492.2966 | AD65: 579.1395 | AE65: 455.95767 | AF65: 1158.801 | AG65: 789.6374 | AH65: 279.94327 | AI65: #N/A | AJ65: 366.5606 | AK65: 125.32595 | AL65: 137.4503 | AM65: 544.8645 | AN65: 247.14447 | AO65: 853.4278 | AP65: 309.9256 | AQ65: 240.7164 | AR65: 150.0424 | AS65: 236.85648 | AT65: 221.70981 | AU65: 302.39236 | AV65: 162.25322
A66: 40451 | B66: 15141.607 | C66: 6010.936 | D66: 2520.5508 | E66: 2593.8599 | F66: 1602.792 | G66: 618.17615 | H66: 3410.0251 | I66: 1252.2802 | J66: 834.5309 | K66: 477.77274 | L66: 317.9663 | M66: 1391.4641 | N66: 2078.3188 | O66: 235.16885 | P66: 242.27264 | Q66: 472.6645 | R66: 243.27103 | S66: 233.67525 | T66: 427.90927 | U66: 218.00572 | V66: 145.39822 | W66: 382.0506 | X66: 233.68451 | Y66: 6261.8823 | Z66: 1538.0596 | AA66: 446.62817 | AB66: 1175.5491 | AC66: 2281.7485 | AD66: 515.1838 | AE66: 421.05072 | AF66: 1100.311 | AG66: 794.07214 | AH66: 263.057 | AI66: #N/A | AJ66: 342.83844 | AK66: 108.14431 | AL66: 128.04236 | AM66: 452.73785 | AN66: 225.60272 | AO66: 789.7709 | AP66: 289.45047 | AQ66: 200.78265 | AR66: 128.46147 | AS66: 255.72375 | AT66: 210.91278 | AU66: 298.2892 | AV66: 152.55551
A67: 40359 | B67: 14980.193 | C67: 5538.6846 | D67: 2403.3303 | E67: 2524.8813 | F67: 1607.9833 | G67: 572.4393 | H67: 3292.6736 | I67: 1202.4994 | J67: 819.4445 | K67: 477.95224 | L67: 308.1724 | M67: 1363.883 | N67: 2050.6501 | O67: 212.24652 | P67: 234.55315 | Q67: 460.4803 | R67: 238.9657 | S67: 230.90788 | T67: 422.5645 | U67: 210.97789 | V67: 140.7545 | W67: 372.05124 | X67: 227.25987 | Y67: 5823.4146 | Z67: 1528.0951 | AA67: 442.5235 | AB67: 1179.3607 | AC67: 2107.2532 | AD67: 512.51196 | AE67: 404.35126 | AF67: 1104.2279 | AG67: 748.3721 | AH67: 246.0123 | AI67: #N/A | AJ67: 331.33066 | AK67: 113.04822 | AL67: 116.71345 | AM67: 435.81824 | AN67: 203.5185 | AO67: 746.93756 | AP67: 284.72842 | AQ67: 206.68237 | AR67: 124.71703 | AS67: 220.84042 | AT67: 200.50847 | AU67: 276.09268 | AV67: 149.36319
A68: 40268 | B68: 14764.61 | C68: 5574.322 | D68: 2477.183 | E68: 2720.3748 | F68: 1580.5444 | G68: 593.5628 | H68: 3519.2158 | I68: 1191.3973 | J68: 871.6965 | K68: 453.74695 | L68: 330.67804 | M68: 1487.1416 | N68: 2087.1543 | O68: 217.82886 | P68: 224.72252 | Q68: 491.1615 | R68: 252.12918 | S68: 224.22911 | T68: 447.7508 | U68: 230.26976 | V68: 141.51877 | W68: 396.71402 | X68: 247.38652 | Y68: 5126.5015 | Z68: 1609.4011 | AA68: 432.41776 | AB68: 1169.4287 | AC68: 1966.9967 | AD68: 505.88928 | AE68: 392.01544 | AF68: 1063.2671 | AG68: 693.4842 | AH68: 233.5096 | AI68: #N/A | AJ68: 324.57626 | AK68: 114.95596 | AL68: 118.27161 | AM68: 448.4117 | AN68: 199.62854 | AO68: 733.32556 | AP68: 301.21875 | AQ68: 187.17975 | AR68: 124.41495 | AS68: 213.65627 | AT68: 211.79195 | AU68: 271.41803 | AV68: 133.26016
A69: 40178 | B69: 14651.249 | C69: 5565.0303 | D69: 2542.8992 | E69: 2886.8535 | F69: 1527.4282 | G69: 607.3461 | H69: 3739.8796 | I69: 1170.7592 | J69: 931.0346 | K69: 503.54727 | L69: 345.9529 | M69: 1579.1901 | N69: 2499.0476 | O69: 233.3719 | P69: 216.08559 | Q69: 521.2467 | R69: 267.66373 | S69: 218.48546 | T69: 443.7295 | U69: 244.8288 | V69: 142.08707 | W69: 426.06552 | X69: 262.26126 | Y69: 5907.1187 | Z69: 1458.1915 | AA69: 420.50555 | AB69: 1104.1698 | AC69: 2117.1948 | AD69: 477.251 | AE69: 381.2819 | AF69: 1015.1553 | AG69: 613.6993 | AH69: 229.23834 | AI69: #N/A | AJ69: 307.93152 | AK69: #N/A | AL69: 110.67828 | AM69: 528.5467 | AN69: 196.77327 | AO69: 716.05304 | AP69: 370.5297 | AQ69: 203.60489 | AR69: 158.8368 | AS69: 214.39587 | AT69: 225.50058 | AU69: 262.41788 | AV69: 138.48372
A70: 40086 | B70: 14448.882 | C70: 5293.814 | D70: 2566.5808 | E70: 2765.082 | F70: 1428.8359 | G70: 579.49646 | H70: 3576.5313 | I70: 1048.8999 | J70: 897.9643 | K70: 440.5344 | L70: 332.22235 | M70: 1531.2578 | N70: 2249.1726 | O70: 217.42435 | P70: 201.32573 | Q70: 502.1543 | R70: 260.04272 | S70: 216.82109 | T70: 411.33902 | U70: 242.32553 | V70: 130.33661 | W70: 410.99466 | X70: 251.78596 | Y70: 5261.2134 | Z70: 1237.5715 | AA70: 391.84274 | AB70: 1033.7657 | AC70: 1827.1572 | AD70: 450.99478 | AE70: 362.457 | AF70: 971.8549 | AG70: 585.13965 | AH70: 207.71173 | AI70: #N/A | AJ70: 287.3189 | AK70: #N/A | AL70: 100.89482 | AM70: 453.41586 | AN70: 177.9139 | AO70: 685.6164 | AP70: 341.6752 | AQ70: 169.2118 | AR70: 139.35785 | AS70: 224.49928 | AT70: 218.69403 | AU70: 252.68898 | AV70: 125.23882
A71: 39994 | B71: 14381.236 | C71: 5159.6284 | D71: 2409.2974 | E71: 2628.2256 | F71: 1325.916 | G71: 547.5953 | H71: 3369.0854 | I71: 952.9846 | J71: 855.039 | K71: 429.17136 | L71: 312.10898 | M71: 1459.5929 | N71: 2142.4622 | O71: 204.73413 | P71: 187.44763 | Q71: 468.45703 | R71: 246.10757 | S71: 201.85582 | T71: 381.1969 | U71: 234.26553 | V71: 114.76736 | W71: 388.70416 | X71: 237.77473 | Y71: 4911.5156 | Z71: 1173.3864 | AA71: 383.80264 | AB71: 966.6501 | AC71: 1547.365 | AD71: 412.5619 | AE71: 326.46307 | AF71: 933.92377 | AG71: 525.3371 | AH71: 191.31134 | AI71: #N/A | AJ71: 272.81998 | AK71: #N/A | AL71: 89.78133 | AM71: 398.7499 | AN71: 166.79143 | AO71: 632.73615 | AP71: 320.00052 | AQ71: 173.36484 | AR71: 125.00256 | AS71: 190.48172 | AT71: 200.67809 | AU71: 223.01082 | AV71: 120.94777
A72: 39903 | B72: 14430.902 | C72: 5331.206 | D72: 2234.449 | E72: 2511.4336 | F72: 1250.081 | G72: 528.02106 | H72: 3207.5972 | I72: 844.6885 | J72: 826.06665 | K72: 375.40186 | L72: 303.7539 | M72: 1405.8339 | N72: 1950.0159 | O72: 200.6773 | P72: 173.47084 | Q72: 446.253 | R72: 238.3713 | S72: 194.38603 | T72: 354.4872 | U72: 224.67671 | V72: 101.23078 | W72: 368.36005 | X72: 225.71255 | Y72: 4328.533 | Z72: 1174.509 | AA72: 369.36826 | AB72: 851.5344 | AC72: 1305.6665 | AD72: 375.40186 | AE72: 274.18332 | AF72: 860.86676 | AG72: 453.73605 | AH72: 182.19069 | AI72: #N/A | AJ72: 259.42383 | AK72: #N/A | AL72: 91.79334 | AM72: 362.04056 | AN72: 152.34671 | AO72: 581.16034 | AP72: 276.5585 | AQ72: 158.93468 | AR72: 106.31811 | AS72: 180.32198 | AT72: 187.84769 | AU72: 200.68132 | AV72: 105.9689
A73: 39813 | B73: 14608.209 | C73: 5443.348 | D73: 2492.0378 | E73: 2595.4968 | F73: 1336.923 | G73: 533.30505 | H73: 3370.5105 | I73: 850.8531 | J73: 859.18134 | K73: 448.33685 | L73: 317.2496 | M73: 1456.1483 | N73: 2253.5505 | O73: 228.62875 | P73: 175.77505 | Q73: 456.27582 | R73: 252.88762 | S73: 206.87384 | T73: 387.8629 | U73: 238.439 | V73: 109.78497 | W73: 376.91483 | X73: 234.8095 | Y73: 5186.421 | Z73: 1201.6982 | AA73: 384.52124 | AB73: 882.64307 | AC73: 1431.8751 | AD73: 387.6257 | AE73: 267.94427 | AF73: 987.12463 | AG73: 474.91223 | AH73: 211.00877 | AI73: #N/A | AJ73: 269.753 | AK73: #N/A | AL73: 85.29271 | AM73: 490.27954 | AN73: 142.3231 | AO73: 651.32336 | AP73: 328.82785 | AQ73: 184.93863 | AR73: 145.77835 | AS73: 180.28606 | AT73: 206.69717 | AU73: 212.65683 | AV73: 116.90407
A74: 39721 | B74: 14898.999 | C74: 4916.2134 | D74: 3038.6448 | E74: 2989.7097 | F74: 1627.6168 | G74: 586.0112 | H74: 3885.5818 | I74: 1118.5033 | J74: 984.15704 | K74: 519.21625 | L74: 368.28427 | M74: 1669.498 | N74: 2443.135 | O74: 223.7151 | P74: 199.52888 | Q74: 531.72455 | R74: 294.99197 | S74: 225.31898 | T74: 508.00958 | U74: 282.21686 | V74: 133.77402 | W74: 441.89743 | X74: 268.89804 | Y74: 4820.949 | Z74: 1246.988 | AA74: 404.93332 | AB74: 1148.36 | AC74: 1950.0048 | AD74: 571.09845 | AE74: 342.04214 | AF74: 1271.1605 | AG74: 575.99744 | AH74: 246.02441 | AI74: #N/A | AJ74: 295.86957 | AK74: #N/A | AL74: 115.76148 | AM74: 571.4715 | AN74: 178.15126 | AO74: 839.1047 | AP74: 368.4333 | AQ74: 175.48187 | AR74: 171.95879 | AS74: 203.8103 | AT74: 255.6872 | AU74: 257.23865 | AV74: 124.30901
A75: 39629 | B75: 14865.701 | C75: 5153.6733 | D75: 3174.2673 | E75: 3118.4753 | F75: 1660.142 | G75: 606.9154 | H75: 4054.2317 | I75: 1156.6279 | J75: 1018.0891 | K75: 587.96027 | L75: 379.79865 | M75: 1746.97 | N75: 2602.287 | O75: 209.96269 | P75: 202.74785 | Q75: 553.5485 | R75: 303.75296 | S75: 225.41205 | T75: 527.434 | U75: 295.01862 | V75: 147.59332 | W75: 460.91617 | X75: 280.5379 | Y75: 4524.9355 | Z75: 1281.0514 | AA75: 447.73688 | AB75: 1188.8765 | AC75: 1858.8523 | AD75: 594.67303 | AE75: 332.6668 | AF75: 1248.5078 | AG75: 527.70703 | AH75: 242.92638 | AI75: #N/A | AJ75: 306.70056 | AK75: #N/A | AL75: 106.14159 | AM75: 570.0445 | AN75: 203.04156 | AO75: 808.92957 | AP75: 370.36688 | AQ75: 187.83614 | AR75: 172.59695 | AS75: 171.4454 | AT75: 255.38307 | AU75: 264.97913 | AV75: 129.79582
A76: 39538 | B76: 14706.538 | C76: 5155.022 | D76: 3163.9458 | E76: 2994.1099 | F76: 1630.7634 | G76: 578.06866 | H76: 3900.427 | I76: 1082.3529 | J76: 968.2002 | K76: 521.9114 | L76: 361.9713 | M76: 1668.9574 | N76: 2353.5662 | O76: 214.90222 | P76: 198.53 | Q76: 527.47345 | R76: 290.8006 | S76: 208.81754 | T76: 489.03723 | U76: 287.95282 | V76: 150.40839 | W76: 435.70523 | X76: 268.87524 | Y76: 3874.887 | Z76: 1394.8624 | AA76: 429.02817 | AB76: 1234.0236 | AC76: 1639.7223 | AD76: 525.2327 | AE76: 336.74255 | AF76: 1167.6561 | AG76: 479.8864 | AH76: 225.8938 | AI76: #N/A | AJ76: 294.37796 | AK76: #N/A | AL76: 92.69301 | AM76: 501.9051 | AN76: 208.75835 | AO76: 828.4989 | AP76: 333.8184 | AQ76: 175.34671 | AR76: 146.33467 | AS76: 162.66147 | AT76: 234.29874 | AU76: 241.6883 | AV76: 113.43991
A77: 39447 | B77: 14715.058 | C77: 4791.0786 | D77: 3222.9775 | E77: 2847.262 | F77: 1636.0978 | G77: 532.7225 | H77: 3734.7742 | I77: 1035.8115 | J77: 920.3924 | K77: 554.6779 | L77: 347.99057 | M77: 1596.0585 | N77: 2530.829 | O77: 236.04123 | P77: 193.83546 | Q77: 503.45978 | R77: 278.59647 | S77: 194.36862 | T77: 462.61835 | U77: 285.24777 | V77: 144.15031 | W77: 416.08475 | X77: 258.93842 | Y77: 4232.772 | Z77: 1339.0767 | AA77: 427.09702 | AB77: 1278.2108 | AC77: 1628.0137 | AD77: 474.49646 | AE77: 361.81598 | AF77: 1151.6002 | AG77: 448.63992 | AH77: 218.52922 | AI77: #N/A | AJ77: 281.46576 | AK77: #N/A | AL77: 84.880684 | AM77: 526.77563 | AN77: 183.52055 | AO77: 792.21204 | AP77: 352.61368 | AQ77: 188.14848 | AR77: 161.17685 | AS77: 160.46179 | AT77: 212.4979 | AU77: 221.70683 | AV77: 113.28647
A78: 39353 | B78: 14564.117 | C78: 4598.93 | D78: 3160.0679 | E78: 2679.519 | F78: 1513.2936 | G78: 504.0838 | H78: 3512.9846 | I78: 967.5838 | J78: 859.9459 | K78: 470.68832 | L78: 322.2446 | M78: 1483.915 | N78: 2197.9026 | O78: 217.13731 | P78: 183.36891 | Q78: 474.08426 | R78: 258.76785 | S78: 178.62222 | T78: 414.6804 | U78: 265.91034 | V78: 138.22939 | W78: 390.1189 | X78: 241.34547 | Y78: 3677.321 | Z78: 1135.6422 | AA78: 409.80942 | AB78: 1231.2926 | AC78: 1443.8339 | AD78: 419.6473 | AE78: 332.32657 | AF78: 1106.266 | AG78: 445.9806 | AH78: 198.45564 | AI78: #N/A | AJ78: 266.8782 | AK78: #N/A | AL78: 73.14924 | AM78: 422.34576 | AN78: 175.25688 | AO78: 700.5942 | AP78: 321.1458 | AQ78: 151.2634 | AR78: 142.85185 | AS78: 155.42653 | AT78: 192.09415 | AU78: 212.36696 | AV78: 102.43117
A79: 39262 | B79: 14402.082 | C79: 4533.836 | D79: 3082.7349 | E79: 2604.7776 | F79: 1436.7711 | G79: 488.34933 | H79: 3416.949 | I79: 935.6055 | J79: 833.14496 | K79: 491.903 | L79: 310.05725 | M79: 1444.4973 | N79: 2183.3022 | O79: 197.66223 | P79: 178.18858 | Q79: 461.33182 | R79: 250.63129 | S79: 176.80093 | T79: 391.06525 | U79: 267.6993 | V79: 134.20837 | W79: 378.37405 | X79: 235.20488 | Y79: 3375.2788 | Z79: 1092.5072 | AA79: 397.81042 | AB79: 1208.5713 | AC79: 1353.04 | AD79: 399.01074 | AE79: 325.2734 | AF79: 1094.9446 | AG79: 429.83423 | AH79: 186.56436 | AI79: #N/A | AJ79: 255.8236 | AK79: #N/A | AL79: 65.73838 | AM79: 401.783 | AN79: 172.78348 | AO79: 647.891 | AP79: 308.13004 | AQ79: 151.99982 | AR79: 138.12189 | AS79: 135.20009 | AT79: 181.7421 | AU79: 206.9961 | AV79: 101.67458
A80: 39171 | B80: 14215.651 | C80: 4581.2197 | D80: 2959.7 | E80: 2501.342 | F80: 1320.0464 | G80: 474.58154 | H80: 3292.107 | I80: 871.43854 | J80: 802.3949 | K80: 447.29776 | L80: 302.69934 | M80: 1384.5616 | N80: 1991.9304 | O80: 195.59349 | P80: 169.13535 | Q80: 445.00513 | R80: 237.99568 | S80: 165.83833 | T80: 370.03296 | U80: 260.04523 | V80: 122.90347 | W80: 363.4179 | X80: 226.71974 | Y80: 2947.0798 | Z80: 1086.7175 | AA80: 392.586 | AB80: 1166.9987 | AC80: 1198.7665 | AD80: 370.91013 | AE80: 312.98282 | AF80: 1055.3654 | AG80: 404.12198 | AH80: 171.78853 | AI80: #N/A | AJ80: 248.91032 | AK80: #N/A | AL80: 53.559437 | AM80: 364.2348 | AN80: 163.36726 | AO80: 609.9196 | AP80: 276.95798 | AQ80: 135.97154 | AR80: 120.38435 | AS80: 128.66933 | AT80: 176.72661 | AU80: 186.65057 | AV80: 92.00092
... A88: 38442 | B88: 12767.286 | C88: 5112.517 | D88: 2585.1716 | E88: 2273.812 | F88: 1125.299 | G88: 437.6165 | H88: 3011.6206 | I88: 726.5698 | J88: 709.78625 | K88: 395.52536 | L88: 272.7705 | M88: 1179.4376 | N88: 1824.6268 | O88: 168.132 | P88: 124.84875 | Q88: 399.00098 | R88: 215.24834 | S88: 139.96577 | T88: 302.98523 | U88: 217.58704 | V88: 111.97218 | W88: 322.51987 | X88: 204.24622 | Y88: 1955.0988 | Z88: 814.8123 | AA88: 373.50052 | AB88: 948.75146 | AC88: 749.50305 | AD88: 298.4092 | AE88: 292.47238 | AF88: 867.64636 | AG88: 272.50253 | AH88: 133.19783 | AI88: #N/A | AJ88: 188.65193 | AK88: #N/A | AL88: 32.975178 | AM88: 298.7028 | AN88: 111.77416 | AO88: 488.89627 | AP88: 235.6879 | AQ88: 98.596886 | AR88: 104.40427 | AS88: 91.49189 | AT88: 140.99063 | AU88: 138.23068 | AV88: 69.11914
A89: 38352 | B89: 12527.214 | C89: 5046.832 | D89: 2529.4045 | E89: 2228.3804 | F89: 1119.424 | G89: 432.38397 | H89: 2967.7222 | I89: 693.9516 | J89: 696.30145 | K89: 431.72144 | L89: 268.87616 | M89: 1148.3427 | N89: 2051.9668 | O89: 181.05902 | P89: 121.78853 | Q89: 391.25647 | R89: 210.06635 | S89: 138.75711 | T89: 294.3404 | U89: 208.60489 | V89: 108.76734 | W89: 317.2335 | X89: 200.5915 | Y89: 2258.924 | Z89: 764.3451 | AA89: 352.5081 | AB89: 879.87714 | AC89: 755.2354 | AD89: #N/A | AE89: 284.07928 | AF89: 849.91815 | AG89: 262.96442 | AH89: 136.10184 | AI89: #N/A | AJ89: 182.13704 | AK89: #N/A | AL89: 30.87812 | AM89: 316.37836 | AN89: 107.56153 | AO89: 434.69547 | AP89: 258.44434 | AQ89: 106.21992 | AR89: 118.97044 | AS89: 84.11157 | AT89: 133.64453 | AU89: 126.08851 | AV89: 70.19823
...

Sheet MARKET_CAP
A1: MARKET_CAP | B1: 미국 | C1: 일본 | D1: 영국 | E1: 프랑스 | F1: 캐나다 | G1: 스위스 | H1: 독일 | I1: 호주 | J1: 네덜란드 | K1: 스웨덴 | L1: 덴마크 | M1: 스페인 | N1: 이탈리아 | O1: 홍콩 | P1: 싱가포르 | Q1: 벨기에 | R1: 핀란드 | S1: 이스라엘 | T1: 노르웨이 | U1: 아일랜드 | V1: 뉴질랜드 | W1: 오스트리아 | X1: 포르투갈 | Y1: 중국 | Z1: 인도 | AA1: 대만 | AB1: 한국 | AC1: 브라질 | AD1: 사우디아라비아 | AE1: 남아프리카공화국 | AF1: 멕시코 | AG1: 인도네시아 | AH1: 말레이시아 | AI1: 아랍에미리트 | AJ1: 태국 | AK1: 쿠웨이트 | AL1: 카타르 | AM1: 폴란드 | AN1: 칠레 | AO1: 튀르키예 | AP1: 그리스 | AQ1: 필리핀 | AR1: 헝가리 | AS1: 이집트 | AT1: 체코 | AU1: 콜롬비아 | AV1: 페루
A2: USD Millions | B2: USA | C2: Japan | D2: UK | E2: France | F2: Canada | G2: Switzerland | H2: Germany | I2: Australia | J2: Netherlands | K2: Sweden | L2: Denmark | M2: Spain | N2: Italy | O2: Hong Kong | P2: Singapore | Q2: Belgium | R2: Finland | S2: Israel | T2: Norway | U2: Ireland | V2: New Zealand | W2: Austria | X2: Portugal | Y2: China | Z2: India | AA2: Taiwan | AB2: Korea | AC2: Brazil | AD2: Saudi Arabia | AE2: South Africa | AF2: Mexico | AG2: Indonesia | AH2: Malaysia | AI2: UAE | AJ2: Thailand | AK2: Kuwait | AL2: Qatar | AM2: Poland | AN2: Chile | AO2: Turkey | AP2: Greece | AQ2: Philippines | AR2: Hungary | AS2: Egypt | AT2: Czech Republic | AU2: Colombia | AV2: Peru
A3: Date | B3: 984000 | C3: 939200 | D3: 982600 | E3: 925000 | F3: 912400 | G3: 975600 | H3: 928000 | I3: 903600 | J3: 952800 | K3: 975200 | L3: 920800 | M3: 972400 | N3: 938000 | O3: 934400 | P3: 998100 | Q3: 905600 | R3: 924600 | S3: MS300400 | T3: 957800 | U3: 937200 | V3: 955400 | W3: 904000 | X3: 962000 | Y3: MS302400 | Z3: 935600 | AA3: 915800 | AB3: 941000 | AC3: 907600 | AD3: MS705405 | AE3: 971000 | AF3: 848400 | AG3: 105767 | AH3: 105768 | AI3: MS133717 | AJ3: 105769 | AK3: MS133713 | AL3: MS133715 | AM3: 961600 | AN3: 915200 | AO3: 979200 | AP3: 930000 | AQ3: 860800 | AR3: 934800 | AS3: 105766 | AT3: 920000 | AU3: 917000 | AV3: 960400
A4: 03/17/2026 | B4: =_xll.FDS(B3,"FG_MCAP_IDX(3/17/2026,,,USD)") -> #NAME? | C4: =_xll.FDS(C3,"FG_MCAP_IDX(3/17/2026,,,USD)") -> #NAME? | D4: =_xll.FDS(D3,"FG_MCAP_IDX(3/17/2026,,,USD)") -> #NAME? | E4: =_xll.FDS(E3,"FG_MCAP_IDX(3/17/2026,,,USD)") -> #NAME? | F4: =_xll.FDS(F3,"FG_MCAP_IDX(3/17/2026,,,USD)") -> #NAME? | G4: =_xll.FDS(G3,"FG_MCAP_IDX(3/17/2026,,,USD)") -> #NAME? | H4: =_xll.FDS(H3,"FG_MCAP_IDX(3/17/2026,,,USD)") -> #NAME? | I4: =_xll.FDS(I3,"FG_MCAP_IDX(3/17/2026,,,USD)") -> #NAME? | ... AV4: =_xll.FDS(AV3,"FG_MCAP_IDX(3/17/2026,,,USD)") -> #NAME?
A5: {=_xll.FDS("990100","P_DATE(3/17/2026,1/1/2000,M)")} -> #NAME? | B5: {=_xll.FDS(B3,"FG_MCAP_IDX(2/27/2026,1/29/2000,M,USD)")} -> #NAME? | C5: {=_xll.FDS(C3,"FG_MCAP_IDX(2/27/2026,1/29/2000,M,USD)")} -> #NAME? | D5: {=_xll.FDS(D3,"FG_MCAP_IDX(2/27/2026,1/29/2000,M,USD)")} -> #NAME? | E5: {=_xll.FDS(E3,"FG_MCAP_IDX(2/27/2026,1/29/2000,M,USD)")} -> #NAME? | F5: {=_xll.FDS(F3,"FG_MCAP_IDX(2/27/2026,1/29/2000,M,USD)")} -> #NAME? | G5: {=_xll.FDS(G3,"FG_MCAP_IDX(2/27/2026,1/29/2000,M,USD)")} -> #NAME? | H5: {=_xll.FDS(H3,"FG_MCAP_IDX(2/27/2026,1/29/2000,M,USD)")} -> #NAME? | I5: {=_xll.FDS(I3,"FG_MCAP_IDX(2/27/2026,1/29/2000,M,USD)")} -> #NAME? | ... AV5: {=_xll.FDS(AV3,"FG_MCAP_IDX(2/27/2026,1/29/2000,M,USD)")} -> #NAME?
A6: #NAME? | B6: #NAME? | C6: #NAME? | D6: #NAME? | E6: #NAME? | F6: #NAME? | G6: #NAME? | H6: #NAME? | I6: #NAME? | J6: #NAME? | K6: #NAME? | L6: #NAME? | M6: #NAME? | N6: #NAME? | O6: #NAME? | P6: #NAME? | Q6: #NAME? | R6: #NAME? | S6: #NAME? | T6: #NAME? | U6: #NAME? | V6: #NAME? | W6: #NAME? | X6: #NAME? | Y6: #NAME? | Z6: #NAME? | AA6: #NAME? | AB6: #NAME? | AC6: #NAME? | AD6: #NAME? | AE6: #NAME? | AF6: #NAME? | AG6: #NAME? | AH6: #NAME? | AI6: #NAME? | AJ6: #NAME? | AK6: #NAME? | AL6: #NAME? | AM6: #NAME? | AN6: #NAME? | AO6: #NAME? | AP6: #NAME? | AQ6: #NAME? | AR6: #NAME? | AS6: #NAME? | AT6: #NAME? | AU6: #NAME? | AV6: #NAME?
A7: #NAME? | B7: #NAME? | C7: #NAME? | D7: #NAME? | E7: #NAME? | F7: #NAME? | G7: #NAME? | H7: #NAME? | I7: #NAME? | J7: #NAME? | K7: #NAME? | L7: #NAME? | M7: #NAME? | N7: #NAME? | O7: #NAME? | P7: #NAME? | Q7: #NAME? | R7: #NAME? | S7: #NAME? | T7: #NAME? | U7: #NAME? | V7: #NAME? | W7: #NAME? | X7: #NAME? | Y7: #NAME? | Z7: #NAME? | AA7: #NAME? | AB7: #NAME? | AC7: #NAME? | AD7: #NAME? | AE7: #NAME? | AF7: #NAME? | AG7: #NAME? | AH7: #NAME? | AI7: #NAME? | AJ7: #NAME? | AK7: #NAME? | AL7: #NAME? | AM7: #NAME? | AN7: #NAME? | AO7: #NAME? | AP7: #NAME? | AQ7: #NAME? | AR7: #NAME? | AS7: #NAME? | AT7: #NAME? | AU7: #NAME? | AV7: #NAME?
A8: #NAME? | B8: #NAME? | C8: #NAME? | D8: #NAME? | E8: #NAME? | F8: #NAME? | G8: #NAME? | H8: #NAME? | I8: #NAME? | J8: #NAME? | K8: #NAME? | L8: #NAME? | M8: #NAME? | N8: #NAME? | O8: #NAME? | P8: #NAME? | Q8: #NAME? | R8: #NAME? | S8: #NAME? | T8: #NAME? | U8: #NAME? | V8: #NAME? | W8: #NAME? | X8: #NAME? | Y8: #NAME? | Z8: #NAME? | AA8: #NAME? | AB8: #NAME? | AC8: #NAME? | AD8: #NAME? | AE8: #NAME? | AF8: #NAME? | AG8: #NAME? | AH8: #NAME? | AI8: #NAME? | AJ8: #NAME? | AK8: #NAME? | AL8: #NAME? | AM8: #NAME? | AN8: #NAME? | AO8: #NAME? | AP8: #NAME? | AQ8: #NAME? | AR8: #NAME? | AS8: #NAME? | AT8: #NAME? | AU8: #NAME? | AV8: #NAME?
A9: #NAME? | B9: #NAME? | C9: #NAME? | D9: #NAME? | E9: #NAME? | F9: #NAME? | G9: #NAME? | H9: #NAME? | I9: #NAME? | J9: #NAME? | K9: #NAME? | L9: #NAME? | M9: #NAME? | N9: #NAME? | O9: #NAME? | P9: #NAME? | Q9: #NAME? | R9: #NAME? | S9: #NAME? | T9: #NAME? | U9: #NAME? | V9: #NAME? | W9: #NAME? | X9: #NAME? | Y9: #NAME? | Z9: #NAME? | AA9: #NAME? | AB9: #NAME? | AC9: #NAME? | AD9: #NAME? | AE9: #NAME? | AF9: #NAME? | AG9: #NAME? | AH9: #NAME? | AI9: #NAME? | AJ9: #NAME? | AK9: #NAME? | AL9: #NAME? | AM9: #NAME? | AN9: #NAME? | AO9: #NAME? | AP9: #NAME? | AQ9: #NAME? | AR9: #NAME? | AS9: #NAME? | AT9: #NAME? | AU9: #NAME? | AV9: #NAME?
A10: #NAME? | B10: #NAME? | C10: #NAME? | D10: #NAME? | E10: #NAME? | F10: #NAME? | G10: #NAME? | H10: #NAME? | I10: #NAME? | J10: #NAME? | K10: #NAME? | L10: #NAME? | M10: #NAME? | N10: #NAME? | O10: #NAME? | P10: #NAME? | Q10: #NAME? | R10: #NAME? | S10: #NAME? | T10: #NAME? | U10: #NAME? | V10: #NAME? | W10: #NAME? | X10: #NAME? | Y10: #NAME? | Z10: #NAME? | AA10: #NAME? | AB10: #NAME? | AC10: #NAME? | AD10: #NAME? | AE10: #NAME? | AF10: #NAME? | AG10: #NAME? | AH10: #NAME? | AI10: #NAME? | AJ10: #NAME? | AK10: #NAME? | AL10: #NAME? | AM10: #NAME? | AN10: #NAME? | AO10: #NAME? | AP10: #NAME? | AQ10: #NAME? | AR10: #NAME? | AS10: #NAME? | AT10: #NAME? | AU10: #NAME? | AV10: #NAME?
A11: #NAME? | B11: #NAME? | C11: #NAME? | D11: #NAME? | E11: #NAME? | F11: #NAME? | G11: #NAME? | H11: #NAME? | I11: #NAME? | J11: #NAME? | K11: #NAME? | L11: #NAME? | M11: #NAME? | N11: #NAME? | O11: #NAME? | P11: #NAME? | Q11: #NAME? | R11: #NAME? | S11: #NAME? | T11: #NAME? | U11: #NAME? | V11: #NAME? | W11: #NAME? | X11: #NAME? | Y11: #NAME? | Z11: #NAME? | AA11: #NAME? | AB11: #NAME? | AC11: #NAME? | AD11: #NAME? | AE11: #NAME? | AF11: #NAME? | AG11: #NAME? | AH11: #NAME? | AI11: #NAME? | AJ11: #NAME? | AK11: #NAME? | AL11: #NAME? | AM11: #NAME? | AN11: #NAME? | AO11: #NAME? | AP11: #NAME? | AQ11: #NAME? | AR11: #NAME? | AS11: #NAME? | AT11: #NAME? | AU11: #NAME? | AV11: #NAME?
A12: #NAME? | B12: #NAME? | C12: #NAME? | D12: #NAME? | E12: #NAME? | F12: #NAME? | G12: #NAME? | H12: #NAME? | I12: #NAME? | J12: #NAME? | K12: #NAME? | L12: #NAME? | M12: #NAME? | N12: #NAME? | O12: #NAME? | P12: #NAME? | Q12: #NAME? | R12: #NAME? | S12: #NAME? | T12: #NAME? | U12: #NAME? | V12: #NAME? | W12: #NAME? | X12: #NAME? | Y12: #NAME? | Z12: #NAME? | AA12: #NAME? | AB12: #NAME? | AC12: #NAME? | AD12: #NAME? | AE12: #NAME? | AF12: #NAME? | AG12: #NAME? | AH12: #NAME? | AI12: #NAME? | AJ12: #NAME? | AK12: #NAME? | AL12: #NAME? | AM12: #NAME? | AN12: #NAME? | AO12: #NAME? | AP12: #NAME? | AQ12: #NAME? | AR12: #NAME? | AS12: #NAME? | AT12: #NAME? | AU12: #NAME? | AV12: #NAME?
A13: #NAME? | B13: #NAME? | C13: #NAME? | D13: #NAME? | E13: #NAME? | F13: #NAME? | G13: #NAME? | H13: #NAME? | I13: #NAME? | J13: #NAME? | K13: #NAME? | L13: #NAME? | M13: #NAME? | N13: #NAME? | O13: #NAME? | P13: #NAME? | Q13: #NAME? | R13: #NAME? | S13: #NAME? | T13: #NAME? | U13: #NAME? | V13: #NAME? | W13: #NAME? | X13: #NAME? | Y13: #NAME? | Z13: #NAME? | AA13: #NAME? | AB13: #NAME? | AC13: #NAME? | AD13: #NAME? | AE13: #NAME? | AF13: #NAME? | AG13: #NAME? | AH13: #NAME? | AI13: #NAME? | AJ13: #NAME? | AK13: #NAME? | AL13: #NAME? | AM13: #NAME? | AN13: #NAME? | AO13: #NAME? | AP13: #NAME? | AQ13: #NAME? | AR13: #NAME? | AS13: #NAME? | AT13: #NAME? | AU13: #NAME? | AV13: #NAME?
A14: #NAME? | B14: #NAME? | C14: #NAME? | D14: #NAME? | E14: #NAME? | F14: #NAME? | G14: #NAME? | H14: #NAME? | I14: #NAME? | J14: #NAME? | K14: #NAME? | L14: #NAME? | M14: #NAME? | N14: #NAME? | O14: #NAME? | P14: #NAME? | Q14: #NAME? | R14: #NAME? | S14: #NAME? | T14: #NAME? | U14: #NAME? | V14: #NAME? | W14: #NAME? | X14: #NAME? | Y14: #NAME? | Z14: #NAME? | AA14: #NAME? | AB14: #NAME? | AC14: #NAME? | AD14: #NAME? | AE14: #NAME? | AF14: #NAME? | AG14: #NAME? | AH14: #NAME? | AI14: #NAME? | AJ14: #NAME? | AK14: #NAME? | AL14: #NAME? | AM14: #NAME? | AN14: #NAME? | AO14: #NAME? | AP14: #NAME? | AQ14: #NAME? | AR14: #NAME? | AS14: #NAME? | AT14: #NAME? | AU14: #NAME? | AV14: #NAME?
A15: #NAME? | B15: #NAME? | C15: #NAME? | D15: #NAME? | E15: #NAME? | F15: #NAME? | G15: #NAME? | H15: #NAME? | I15: #NAME? | J15: #NAME? | K15: #NAME? | L15: #NAME? | M15: #NAME? | N15: #NAME? | O15: #NAME? | P15: #NAME? | Q15: #NAME? | R15: #NAME? | S15: #NAME? | T15: #NAME? | U15: #NAME? | V15: #NAME? | W15: #NAME? | X15: #NAME? | Y15: #NAME? | Z15: #NAME? | AA15: #NAME? | AB15: #NAME? | AC15: #NAME? | AD15: #NAME? | AE15: #NAME? | AF15: #NAME? | AG15: #NAME? | AH15: #NAME? | AI15: #NAME? | AJ15: #NAME? | AK15: #NAME? | AL15: #NAME? | AM15: #NAME? | AN15: #NAME? | AO15: #NAME? | AP15: #NAME? | AQ15: #NAME? | AR15: #NAME? | AS15: #NAME? | AT15: #NAME? | AU15: #NAME? | AV15: #NAME?
A16: #NAME? | B16: #NAME? | C16: #NAME? | D16: #NAME? | E16: #NAME? | F16: #NAME? | G16: #NAME? | H16: #NAME? | I16: #NAME? | J16: #NAME? | K16: #NAME? | L16: #NAME? | M16: #NAME? | N16: #NAME? | O16: #NAME? | P16: #NAME? | Q16: #NAME? | R16: #NAME? | S16: #NAME? | T16: #NAME? | U16: #NAME? | V16: #NAME? | W16: #NAME? | X16: #NAME? | Y16: #NAME? | Z16: #NAME? | AA16: #NAME? | AB16: #NAME? | AC16: #NAME? | AD16: #NAME? | AE16: #NAME? | AF16: #NAME? | AG16: #NAME? | AH16: #NAME? | AI16: #NAME? | AJ16: #NAME? | AK16: #NAME? | AL16: #NAME? | AM16: #NAME? | AN16: #NAME? | AO16: #NAME? | AP16: #NAME? | AQ16: #NAME? | AR16: #NAME? | AS16: #NAME? | AT16: #NAME? | AU16: #NAME? | AV16: #NAME?
A17: #NAME? | B17: #NAME? | C17: #NAME? | D17: #NAME? | E17: #NAME? | F17: #NAME? | G17: #NAME? | H17: #NAME? | I17: #NAME? | J17: #NAME? | K17: #NAME? | L17: #NAME? | M17: #NAME? | N17: #NAME? | O17: #NAME? | P17: #NAME? | Q17: #NAME? | R17: #NAME? | S17: #NAME? | T17: #NAME? | U17: #NAME? | V17: #NAME? | W17: #NAME? | X17: #NAME? | Y17: #NAME? | Z17: #NAME? | AA17: #NAME? | AB17: #NAME? | AC17: #NAME? | AD17: #NAME? | AE17: #NAME? | AF17: #NAME? | AG17: #NAME? | AH17: #NAME? | AI17: #NAME? | AJ17: #NAME? | AK17: #NAME? | AL17: #NAME? | AM17: #NAME? | AN17: #NAME? | AO17: #NAME? | AP17: #NAME? | AQ17: #NAME? | AR17: #NAME? | AS17: #NAME? | AT17: #NAME? | AU17: #NAME? | AV17: #NAME?
... A318: #NAME? | B318: #NAME? | C318: #NAME? | D318: #NAME? | E318: #NAME? | F318: #NAME? | G318: #NAME? | H318: #NAME? | I318: #NAME? | J318: #NAME? | K318: #NAME? | L318: #NAME? | M318: #NAME? | N318: #NAME? | O318: #NAME? | P318: #NAME? | Q318: #NAME? | R318: #NAME? | S318: #NAME? | T318: #NAME? | U318: #NAME? | V318: #NAME? | W318: #NAME? | X318: #NAME? | Y318: #NAME? | Z318: #NAME? | AA318: #NAME? | AB318: #NAME? | AC318: #NAME? | AD318: #NAME? | AE318: #NAME? | AF318: #NAME? | AG318: #NAME? | AH318: #NAME? | AI318: #NAME? | AJ318: #NAME? | AK318: #NAME? | AL318: #NAME? | AM318: #NAME? | AN318: #NAME? | AO318: #NAME? | AP318: #NAME? | AQ318: #NAME? | AR318: #NAME? | AS318: #NAME? | AT318: #NAME? | AU318: #NAME? | AV318: #NAME?

Sheet Sheet5
A1: MARKET_CAP | B1: 미국 | C1: 일본 | D1: 영국 | E1: 프랑스 | F1: 캐나다 | G1: 스위스 | H1: 독일 | I1: 호주 | J1: 네덜란드 | K1: 스웨덴 | L1: 덴마크 | M1: 스페인 | N1: 이탈리아 | O1: 홍콩 | P1: 싱가포르 | Q1: 벨기에 | R1: 핀란드 | S1: 이스라엘 | T1: 노르웨이 | U1: 아일랜드 | V1: 뉴질랜드 | W1: 오스트리아 | X1: 포르투갈 | Y1: 중국 | Z1: 인도 | AA1: 대만 | AB1: 한국 | AC1: 브라질 | AD1: 사우디아라비아 | AE1: 남아프리카공화국 | AF1: 멕시코 | AG1: 인도네시아 | AH1: 말레이시아 | AI1: 아랍에미리트 | AJ1: 태국 | AK1: 쿠웨이트 | AL1: 카타르 | AM1: 폴란드 | AN1: 칠레 | AO1: 튀르키예 | AP1: 그리스 | AQ1: 필리핀 | AR1: 헝가리 | AS1: 이집트 | AT1: 체코 | AU1: 콜롬비아 | AV1: 페루
A2: USD Millions | B2: USA | C2: Japan | D2: UK | E2: France | F2: Canada | G2: Switzerland | H2: Germany | I2: Australia | J2: Netherlands | K2: Sweden | L2: Denmark | M2: Spain | N2: Italy | O2: Hong Kong | P2: Singapore | Q2: Belgium | R2: Finland | S2: Israel | T2: Norway | U2: Ireland | V2: New Zealand | W2: Austria | X2: Portugal | Y2: China | Z2: India | AA2: Taiwan | AB2: Korea | AC2: Brazil | AD2: Saudi Arabia | AE2: South Africa | AF2: Mexico | AG2: Indonesia | AH2: Malaysia | AI2: UAE | AJ2: Thailand | AK2: Kuwait | AL2: Qatar | AM2: Poland | AN2: Chile | AO2: Turkey | AP2: Greece | AQ2: Philippines | AR2: Hungary | AS2: Egypt | AT2: Czech Republic | AU2: Colombia | AV2: Peru
A3: Date | B3: 984000 | C3: 939200 | D3: 982600 | E3: 925000 | F3: 912400 | G3: 975600 | H3: 928000 | I3: 903600 | J3: 952800 | K3: 975200 | L3: 920800 | M3: 972400 | N3: 938000 | O3: 934400 | P3: 998100 | Q3: 905600 | R3: 924600 | S3: MS300400 | T3: 957800 | U3: 937200 | V3: 955400 | W3: 904000 | X3: 962000 | Y3: MS302400 | Z3: 935600 | AA3: 915800 | AB3: 941000 | AC3: 907600 | AD3: MS705405 | AE3: 971000 | AF3: 848400 | AG3: 105767 | AH3: 105768 | AI3: MS133717 | AJ3: 105769 | AK3: MS133713 | AL3: MS133715 | AM3: 961600 | AN3: 915200 | AO3: 979200 | AP3: 930000 | AQ3: 860800 | AR3: 934800 | AS3: 105766 | AT3: 920000 | AU3: 917000 | AV3: 960400
